<?xml version='1.0'?>
<sdf version="1.4" xmlns:xacro="http://www.ros.org/wiki/xacro" >
  <xacro:property name="pi" value="3.14159265"/>

  <xacro:macro name="gbeam_link" params="suffix pose">
    <link name="gbeam_link${suffix}">
      <gravity>1</gravity>
      <self_collide>1</self_collide>

      <pose>${pose}</pose>

      <inertial>
        <mass>0.3</mass>
        <inertia>
          <ixx>0.001</ixx><ixy>0</ixy>    <ixz>0</ixz>
          <iyy>0.002</iyy><iyz>0</iyz>
          <izz>0.001</izz>
        </inertia>
      </inertial>
      <collision name='collision'>
        <geometry>
          <mesh><uri>file://$(find gbeam_model)/meshes/gbeam_link_5k.stl</uri></mesh>
        </geometry>
        <surface>
          <friction>
            <ode>
              <mu>1.0</mu>
              <mu2>0.7</mu2>
            </ode>
          </friction>
        </surface>
      </collision>

      <visual name='visual'>
        <geometry>
          <mesh><uri>file://$(find gbeam_model)/meshes/gbeam_link_5k.stl</uri></mesh>
        </geometry>
      </visual>
    </link>
  </xacro:macro>

  <xacro:macro name="gbeam_node" params="suffix pose">
    <link name="gbeam_node${suffix}">
      <gravity>1</gravity>
      <self_collide>1</self_collide>

      <pose>${pose}</pose>

      <inertial>
        <mass>0.2</mass>
        <inertia>
          <ixx>0.001</ixx><ixy>0</ixy>    <ixz>0</ixz>
          <iyy>0.001</iyy><iyz>0</iyz>
          <izz>0.001</izz>
        </inertia>
      </inertial>

      <collision name='collision'>
        <geometry>
          <mesh><uri>file://$(find gbeam_model)/meshes/gbeam_node_5k.stl</uri></mesh>
        </geometry>
        <surface>
          <friction>
            <ode>
              <mu>0.5</mu>
              <mu2>0.5</mu2>
            </ode>
          </friction>
        </surface>
      </collision>

      <visual name='visual'>
        <geometry>
          <mesh><uri>file://$(find gbeam_model)/meshes/gbeam_node_5k.stl</uri></mesh>
        </geometry>
      </visual>
    </link>
  </xacro:macro>

  <model name="gbeam_soup">
    <plugin name='hand_of_god' filename="libgazebo_ros_hand_of_god.so">
      <frameId>hog</frameId>
      <linkName>hog</linkName>
      <kl>400</kl>
      <ka>200</ka>
    </plugin>

    <plugin name="assembly_soup" filename="libassembly_soup_plugin.so">

      <!-- Frame that poses are broadcasted in -->
      <tf_world_frame>world</tf_world_frame>

      <!-- Mate Models -->
      <mate_model type="gbeam">
        <!-- planar shear-supporting magnetic mate
             mating surface is along positive z-axis
             -->
        <symmetry>
          <rot>1 1 4</rot>
        </symmetry>

        <attach_threshold>
          <linear>0.01</linear>
          <angular>0.1</angular>
        </attach_threshold>

        <detach_threshold>
          <linear>0.015</linear>
          <angular>0.2</angular>
        </detach_threshold>

        <joint type="prismatic" name="gbeam">
          <pose>0 0.025 0 0 ${pi/2} 0</pose>
          <parent>gbeam_link</parent>
          <child>gbeam_node</child>
          <axis>
            <xyz>0 1 0</xyz>
            <limit><lower>-0.001</lower><upper>0.001</upper></limit>
          </axis>
          <physics>
            <ode>
              <cfm_damping>true</cfm_damping>
              <cfm>0.01</cfm>
              <erp>0.05</erp>
              <limit>
                <cfm>0.1</cfm>
                <erp>0.5</erp>
              </limit>
            </ode>
          </physics>
        </joint>
      </mate_model>

      <!-- Experimental: add a mate point to the hog -->
      <atom_model type="hog">
        <mate_point type="gbeam" gender="female">
          <pose>0 0.025 0 ${pi/2} 0 0</pose>
        </mate_point>
        <mate_point type="gbeam" gender="female">
          <pose>0 -0.025 0 ${pi/2} 0 ${pi}</pose>
        </mate_point>
        <mate_point type="gbeam" gender="female">
          <pose>0 0 0.025 ${pi} 0 0</pose>
        </mate_point>
        <mate_point type="gbeam" gender="female">
          <pose>0 0 -0.025 0 0 0</pose>
        </mate_point>
        <mate_point type="gbeam" gender="female">
          <pose>0.025 0 0 0 -${pi/2.0} 0</pose>
        </mate_point>
        <mate_point type="gbeam" gender="female">
          <pose>-0.025 0 0 0 ${pi/2.0} 0</pose>
        </mate_point>

        <mate_point type="gbeam" gender="male">
          <pose>0 -0.025 0 ${pi/2} 0 0</pose>
        </mate_point>
        <mate_point type="gbeam" gender="male">
          <pose>0 0.025 0 ${pi/2} 0 ${pi}</pose>
        </mate_point>
        <mate_point type="gbeam" gender="male">
          <pose>0 0 -0.025 ${pi} 0 0</pose>
        </mate_point>
        <mate_point type="gbeam" gender="male">
          <pose>0 0 0.025 0 0 0</pose>
        </mate_point>
        <mate_point type="gbeam" gender="male">
          <pose>-0.025 0 0 0 -${pi/2.0} 0</pose>
        </mate_point>
        <mate_point type="gbeam" gender="male">
          <pose>0.025 0 0 0 ${pi/2.0} 0</pose>
        </mate_point>
      </atom_model>

      <!-- Atom Models -->
      <atom_model type="gbeam_link">
        <mate_point type="gbeam" gender="male">
          <pose>0 0.125 0 ${pi/2} ${pi/4} ${pi}</pose>
        </mate_point>
        <mate_point type="gbeam" gender="male">
          <pose>0 -0.125 0 ${pi/2} ${pi/4} 0</pose>
        </mate_point>
      </atom_model>

      <atom_model type="gbeam_node">
        <mate_point type="gbeam" gender="female">
          <pose>0 0.025 0 ${pi/2} 0 0</pose>
        </mate_point>
        <mate_point type="gbeam" gender="female">
          <pose>0 -0.025 0 ${pi/2} 0 ${pi}</pose>
        </mate_point>
        <mate_point type="gbeam" gender="female">
          <pose>0 0 0.025 ${pi} 0 0</pose>
        </mate_point>
        <mate_point type="gbeam" gender="female">
          <pose>0 0 -0.025 0 0 0</pose>
        </mate_point>
        <mate_point type="gbeam" gender="female">
          <pose>0.025 0 0 0 -${pi/2.0} 0</pose>
        </mate_point>
        <mate_point type="gbeam" gender="female">
          <pose>-0.025 0 0 0 ${pi/2.0} 0</pose>
        </mate_point>
      </atom_model>
    </plugin>

    <xacro:gbeam_node suffix="_1" pose="0 0.3 0.1 0 0 0"/>
    <xacro:gbeam_node suffix="_2" pose="0 0.3 0.2 0 0 0"/>
    <xacro:gbeam_node suffix="_3" pose="0 0.3 0.3 0 0 0"/>
    <!--<xacro:gbeam_node suffix="_4" pose="0 0 0.3 0 0 0"/>-->
    <!--<xacro:gbeam_node suffix="_5" pose="0 0 0.4 0 0 0"/>-->

    <xacro:gbeam_link suffix="_1" pose="0 0 0.2 0 0 0"/>
    <xacro:gbeam_link suffix="_2" pose="0.1 0.2 0.2 0 0 0"/>
    <!--<xacro:gbeam_link suffix="_3" pose="0 0.1 0.2 0 0 0"/>-->
    <!--<xacro:gbeam_link suffix="_4" pose="0 0.1 0.3 0 0 0"/>-->
    <!--<xacro:gbeam_link suffix="_5" pose="0 0.1 0.4 0 0 0"/>-->

    <link name ='hog'>
      <self_collide>1</self_collide>
      <pose>0 0 0.4 0 0 0</pose>
      <collision name ='collision'>
        <geometry>
          <sphere><radius>0.025</radius></sphere>
        </geometry>
      </collision>
      <visual name ='visual'>
        <geometry>
          <sphere><radius>0.025</radius></sphere>
        </geometry>
      </visual>
      <inertial>
        <mass>0.3</mass>
        <inertia>
          <ixx>0.001</ixx><ixy>0</ixy>    <ixz>0</ixz>
          <iyy>0.001</iyy><iyz>0</iyz>
          <izz>0.001</izz>
        </inertia>
      </inertial>
    </link>
  </model>
</sdf>

