<?xml version='1.0'?>
<sdf version="1.4" xmlns:xacro="http://www.ros.org/wiki/xacro" >
  <xacro:property name="pi" value="3.14159265"/>

  <!-- GBeam links -->
  <xacro:macro name="gbeam_link" params="suffix pose">
    <link name="gbeam_link${suffix}">
      <gravity>1</gravity>
      <self_collide>1</self_collide>

      <pose>${pose}</pose>

      <inertial>
        <mass>0.3</mass>
        <inertia>
          <ixx>0.001</ixx><ixy>0</ixy>    <ixz>0</ixz>
          <iyy>0.002</iyy><iyz>0</iyz>
          <izz>0.001</izz>
        </inertia>
      </inertial>
      <xacro:unless value="true">
        <collision name='collision'>
          <!-- use full scanned collision mesh -->
          <geometry>
            <mesh><uri>file://$(find gbeam_model)/meshes/gbeam_link_5k.stl</uri></mesh>
          </geometry>
          <surface>
            <friction>
              <ode>
                <mu>1.0</mu>
                <mu2>0.7</mu2>
              </ode>
            </friction>
            <contact>
              <ode>
                <soft_cfm>0.01</soft_cfm>
                <soft_erp>0.05</soft_erp>
              </ode>
            </contact>
          </surface>
        </collision>
      </xacro:unless>
      <xacro:if value="true">
        <collision name='gbeam_link_collision'>
          <pose>0 0 0 0 -0 0</pose>
          <geometry>
            <box>
              <size>0.035 0.24 0.035</size>
            </box>
          </geometry>
          <surface>
            <friction>
              <ode>
                <mu>1.0</mu>
                <mu2>0.7</mu2>
              </ode>
            </friction>
            <contact>
              <ode>
                <soft_cfm>0.01</soft_cfm>
                <soft_erp>0.05</soft_erp>
              </ode>
            </contact>
          </surface>
        </collision>
        <collision name='gbeam_link_collision_gbeam_link_1'>
          <pose>0 0.115 0 1.5707 -0 0</pose>
          <geometry>
            <cylinder>
              <length>0.0127</length>
              <radius>0.028</radius>
            </cylinder>
          </geometry>
          <surface>
            <friction>
              <ode>
                <mu>1.0</mu>
                <mu2>0.7</mu2>
              </ode>
            </friction>
            <contact>
              <ode>
                <soft_cfm>0.01</soft_cfm>
                <soft_erp>0.05</soft_erp>
              </ode>
            </contact>
          </surface>
        </collision>
        <collision name='gbeam_link_collision_gbeam_link_2'>
          <pose>0 -0.115 0 1.5707 -0 0</pose>
          <geometry>
            <cylinder>
              <length>0.0127</length>
              <radius>0.028</radius>
            </cylinder>
          </geometry>
          <surface>
            <friction>
              <ode>
                <mu>1.0</mu>
                <mu2>0.7</mu2>
              </ode>
            </friction>
            <contact>
              <ode>
                <soft_cfm>0.01</soft_cfm>
                <soft_erp>0.05</soft_erp>
              </ode>
            </contact>
          </surface>
        </collision>
      </xacro:if>

      <visual name='visual'>
        <geometry>
          <mesh><uri>file://$(find gbeam_model)/meshes/gbeam_link_5k.stl</uri></mesh>
        </geometry>
      </visual>
    </link>
  </xacro:macro>

  <xacro:macro name="gbeam_node" params="suffix pose">
    <link name="gbeam_node${suffix}">
      <gravity>1</gravity>
      <self_collide>1</self_collide>

      <pose>${pose}</pose>

      <inertial>
        <mass>0.2</mass>
        <inertia>
          <ixx>0.001</ixx><ixy>0</ixy>    <ixz>0</ixz>
          <iyy>0.001</iyy><iyz>0</iyz>
          <izz>0.001</izz>
        </inertia>
      </inertial>

      <collision name='collision'>
        <geometry>
          <mesh><uri>file://$(find gbeam_model)/meshes/gbeam_node_5k.stl</uri></mesh>
        </geometry>
        <surface>
          <friction>
            <ode>
              <mu>0.5</mu>
              <mu2>0.5</mu2>
            </ode>
          </friction>
          <contact>
            <ode>
              <soft_cfm>0.01</soft_cfm>
              <soft_erp>0.05</soft_erp>
            </ode>
          </contact>
        </surface>
      </collision>

      <visual name='visual'>
        <geometry>
          <mesh><uri>file://$(find gbeam_model)/meshes/gbeam_node_5k.stl</uri></mesh>
        </geometry>
      </visual>
    </link>
  </xacro:macro>

  <xacro:macro name="gbeam_hog" params="pose">
    <plugin name='hand_of_god' filename="libgazebo_ros_hand_of_god.so">
      <frameId>hog</frameId>
      <linkName>hog</linkName>
      <kl>400</kl>
      <ka>200</ka>
    </plugin>
    <link name ='hog'>
      <self_collide>1</self_collide>
      <pose>${pose}</pose>
      <collision name ='collision'>
        <geometry>
          <sphere><radius>0.025</radius></sphere>
        </geometry>
      </collision>
      <visual name ='visual'>
        <geometry>
          <sphere><radius>0.025</radius></sphere>
        </geometry>
      </visual>
      <inertial>
        <mass>0.3</mass>
        <inertia>
          <ixx>0.001</ixx><ixy>0</ixy>    <ixz>0</ixz>
          <iyy>0.001</iyy><iyz>0</iyz>
          <izz>0.001</izz>
        </inertia>
      </inertial>
    </link>
  </xacro:macro>

  <!-- GBeam mates -->
  <xacro:macro name="gbeam_mate" params="linear_attach angular_attach linear_detach angular_detach">
    <mate_model type="gbeam">
      <!-- planar shear-supporting magnetic mate
           mating surface is along positive z-axis
             -->
        <symmetry>
          <rot>1 1 4</rot>
        </symmetry>

        <attach_threshold>
          <linear>${linear_attach}</linear>
          <angular>${angular_attach}</angular>
        </attach_threshold>

        <detach_threshold>
          <linear>${linear_detach}</linear>
          <angular>${angular_detach}</angular>
        </detach_threshold>

        <joint type="prismatic" name="gbeam">
          <pose>0 0.025 0 0 ${pi/2} 0</pose>
          <parent>gbeam_link</parent>
          <child>gbeam_node</child>
          <axis>
            <xyz>0 1 0</xyz>
            <limit><lower>-0.001</lower><upper>0.001</upper></limit>
          </axis>
          <physics>
            <ode>
              <cfm_damping>true</cfm_damping>
              <cfm>0.01</cfm>
              <erp>0.05</erp>
              <limit>
                <cfm>0.1</cfm>
                <erp>0.5</erp>
              </limit>
            </ode>
          </physics>
        </joint>
    </mate_model>
  </xacro:macro>

  <!-- GBeam atoms -->
  <xacro:macro name="gbeam_link_atom" params="">
    <atom_model type="gbeam_link">
      <mate_point type="gbeam" gender="male">
        <pose>0 0.125 0 ${pi/2} ${pi/4} ${pi}</pose>
      </mate_point>
      <mate_point type="gbeam" gender="male">
        <pose>0 -0.125 0 ${pi/2} ${pi/4} 0</pose>
      </mate_point>
    </atom_model>
  </xacro:macro>

  <xacro:macro name="gbeam_node_atom" params="">
    <atom_model type="gbeam_node">
      <mate_point type="gbeam" gender="female">
        <pose>0 0.025 0 ${pi/2} 0 0</pose>
      </mate_point>
      <mate_point type="gbeam" gender="female">
        <pose>0 -0.025 0 ${pi/2} 0 ${pi}</pose>
      </mate_point>
      <mate_point type="gbeam" gender="female">
        <pose>0 0 0.025 ${pi} 0 0</pose>
      </mate_point>
      <mate_point type="gbeam" gender="female">
        <pose>0 0 -0.025 0 0 0</pose>
      </mate_point>
      <mate_point type="gbeam" gender="female">
        <pose>0.025 0 0 0 -${pi/2.0} 0</pose>
      </mate_point>
      <mate_point type="gbeam" gender="female">
        <pose>-0.025 0 0 0 ${pi/2.0} 0</pose>
      </mate_point>
    </atom_model>
  </xacro:macro>

  <xacro:macro name="gbeam_hog_atom" params="">
    <atom_model type="hog">
      <mate_point type="gbeam" gender="female">
        <pose>0 0.025 0 ${pi/2} 0 0</pose>
      </mate_point>
      <mate_point type="gbeam" gender="female">
        <pose>0 -0.025 0 ${pi/2} 0 ${pi}</pose>
      </mate_point>
      <mate_point type="gbeam" gender="female">
        <pose>0 0 0.025 ${pi} 0 0</pose>
      </mate_point>
      <mate_point type="gbeam" gender="female">
        <pose>0 0 -0.025 0 0 0</pose>
      </mate_point>
      <mate_point type="gbeam" gender="female">
        <pose>0.025 0 0 0 -${pi/2.0} 0</pose>
      </mate_point>
      <mate_point type="gbeam" gender="female">
        <pose>-0.025 0 0 0 ${pi/2.0} 0</pose>
      </mate_point>

      <mate_point type="gbeam" gender="male">
        <pose>0 -0.025 0 ${pi/2} 0 0</pose>
      </mate_point>
      <mate_point type="gbeam" gender="male">
        <pose>0 0.025 0 ${pi/2} 0 ${pi}</pose>
      </mate_point>
      <mate_point type="gbeam" gender="male">
        <pose>0 0 -0.025 ${pi} 0 0</pose>
      </mate_point>
      <mate_point type="gbeam" gender="male">
        <pose>0 0 0.025 0 0 0</pose>
      </mate_point>
      <mate_point type="gbeam" gender="male">
        <pose>-0.025 0 0 0 -${pi/2.0} 0</pose>
      </mate_point>
      <mate_point type="gbeam" gender="male">
        <pose>0.025 0 0 0 ${pi/2.0} 0</pose>
      </mate_point>
    </atom_model>
  </xacro:macro>
</sdf>
